*********
ERROR LOG
*********

Exception occurred at: 2018-08-06 21:50:35.665278
Traceback (most recent call last):
  File ".\raise-and-assert.py", line 4, in <module>
    raise Exception('This is the error message.')
Exception: This is the error message.

